2016-12-01 15:42:10,842 [Thread-2:10280] [django.request:256] [base:handle_uncaught_exception] [ERROR]- Internal Server Error: /
Traceback (most recent call last):
  File "c:\python\python35\lib\site-packages\django\template\base.py", line 337, in parse
    compile_func = self.tags[command]
KeyError: 'SITE_NAME'

During handling of the above exception, another exception occurred:

Traceback (most recent call last):
  File "c:\python\python35\lib\site-packages\django\core\handlers\base.py", line 132, in get_response
    response = wrapped_callback(request, *callback_args, **callback_kwargs)
  File "C:\Users\array\PycharmProjects\www\blog\views.py", line 8, in index
    return render(request,'index.html',locals())
  File "c:\python\python35\lib\site-packages\django\shortcuts.py", line 67, in render
    template_name, context, request=request, using=using)
  File "c:\python\python35\lib\site-packages\django\template\loader.py", line 98, in render_to_string
    template = get_template(template_name, using=using)
  File "c:\python\python35\lib\site-packages\django\template\loader.py", line 35, in get_template
    return engine.get_template(template_name, dirs)
  File "c:\python\python35\lib\site-packages\django\template\backends\django.py", line 30, in get_template
    return Template(self.engine.get_template(template_name, dirs))
  File "c:\python\python35\lib\site-packages\django\template\engine.py", line 167, in get_template
    template, origin = self.find_template(template_name, dirs)
  File "c:\python\python35\lib\site-packages\django\template\engine.py", line 141, in find_template
    source, display_name = loader(name, dirs)
  File "c:\python\python35\lib\site-packages\django\template\loaders\base.py", line 13, in __call__
    return self.load_template(template_name, template_dirs)
  File "c:\python\python35\lib\site-packages\django\template\loaders\base.py", line 23, in load_template
    template = Template(source, origin, template_name, self.engine)
  File "c:\python\python35\lib\site-packages\django\template\base.py", line 190, in __init__
    self.nodelist = engine.compile_string(template_string, origin)
  File "c:\python\python35\lib\site-packages\django\template\engine.py", line 261, in compile_string
    return parser.parse()
  File "c:\python\python35\lib\site-packages\django\template\base.py", line 339, in parse
    self.invalid_block_tag(token, command, parse_until)
  File "c:\python\python35\lib\site-packages\django\template\base.py", line 395, in invalid_block_tag
    raise self.error(token, "Invalid block tag: '%s'" % command)
django.template.base.TemplateSyntaxError: Invalid block tag: 'SITE_NAME'
2016-12-01 15:42:11,270 [Thread-3:2756] [django.request:256] [base:handle_uncaught_exception] [ERROR]- Internal Server Error: /favicon.ico
Traceback (most recent call last):
  File "c:\python\python35\lib\site-packages\django\template\base.py", line 337, in parse
    compile_func = self.tags[command]
KeyError: 'SITE_NAME'

During handling of the above exception, another exception occurred:

Traceback (most recent call last):
  File "c:\python\python35\lib\site-packages\django\core\handlers\base.py", line 132, in get_response
    response = wrapped_callback(request, *callback_args, **callback_kwargs)
  File "C:\Users\array\PycharmProjects\www\blog\views.py", line 8, in index
    return render(request,'index.html',locals())
  File "c:\python\python35\lib\site-packages\django\shortcuts.py", line 67, in render
    template_name, context, request=request, using=using)
  File "c:\python\python35\lib\site-packages\django\template\loader.py", line 98, in render_to_string
    template = get_template(template_name, using=using)
  File "c:\python\python35\lib\site-packages\django\template\loader.py", line 35, in get_template
    return engine.get_template(template_name, dirs)
  File "c:\python\python35\lib\site-packages\django\template\backends\django.py", line 30, in get_template
    return Template(self.engine.get_template(template_name, dirs))
  File "c:\python\python35\lib\site-packages\django\template\engine.py", line 167, in get_template
    template, origin = self.find_template(template_name, dirs)
  File "c:\python\python35\lib\site-packages\django\template\engine.py", line 141, in find_template
    source, display_name = loader(name, dirs)
  File "c:\python\python35\lib\site-packages\django\template\loaders\base.py", line 13, in __call__
    return self.load_template(template_name, template_dirs)
  File "c:\python\python35\lib\site-packages\django\template\loaders\base.py", line 23, in load_template
    template = Template(source, origin, template_name, self.engine)
  File "c:\python\python35\lib\site-packages\django\template\base.py", line 190, in __init__
    self.nodelist = engine.compile_string(template_string, origin)
  File "c:\python\python35\lib\site-packages\django\template\engine.py", line 261, in compile_string
    return parser.parse()
  File "c:\python\python35\lib\site-packages\django\template\base.py", line 339, in parse
    self.invalid_block_tag(token, command, parse_until)
  File "c:\python\python35\lib\site-packages\django\template\base.py", line 395, in invalid_block_tag
    raise self.error(token, "Invalid block tag: '%s'" % command)
django.template.base.TemplateSyntaxError: Invalid block tag: 'SITE_NAME'
2016-12-01 15:44:38,802 [Thread-2:19352] [django.request:256] [base:handle_uncaught_exception] [ERROR]- Internal Server Error: /
Traceback (most recent call last):
  File "c:\python\python35\lib\site-packages\django\template\base.py", line 337, in parse
    compile_func = self.tags[command]
KeyError: 'SITE_NAME'

During handling of the above exception, another exception occurred:

Traceback (most recent call last):
  File "c:\python\python35\lib\site-packages\django\core\handlers\base.py", line 132, in get_response
    response = wrapped_callback(request, *callback_args, **callback_kwargs)
  File "C:\Users\array\PycharmProjects\www\blog\views.py", line 11, in index
    return render(request,'index.html',locals())
  File "c:\python\python35\lib\site-packages\django\shortcuts.py", line 67, in render
    template_name, context, request=request, using=using)
  File "c:\python\python35\lib\site-packages\django\template\loader.py", line 98, in render_to_string
    template = get_template(template_name, using=using)
  File "c:\python\python35\lib\site-packages\django\template\loader.py", line 35, in get_template
    return engine.get_template(template_name, dirs)
  File "c:\python\python35\lib\site-packages\django\template\backends\django.py", line 30, in get_template
    return Template(self.engine.get_template(template_name, dirs))
  File "c:\python\python35\lib\site-packages\django\template\engine.py", line 167, in get_template
    template, origin = self.find_template(template_name, dirs)
  File "c:\python\python35\lib\site-packages\django\template\engine.py", line 141, in find_template
    source, display_name = loader(name, dirs)
  File "c:\python\python35\lib\site-packages\django\template\loaders\base.py", line 13, in __call__
    return self.load_template(template_name, template_dirs)
  File "c:\python\python35\lib\site-packages\django\template\loaders\base.py", line 23, in load_template
    template = Template(source, origin, template_name, self.engine)
  File "c:\python\python35\lib\site-packages\django\template\base.py", line 190, in __init__
    self.nodelist = engine.compile_string(template_string, origin)
  File "c:\python\python35\lib\site-packages\django\template\engine.py", line 261, in compile_string
    return parser.parse()
  File "c:\python\python35\lib\site-packages\django\template\base.py", line 339, in parse
    self.invalid_block_tag(token, command, parse_until)
  File "c:\python\python35\lib\site-packages\django\template\base.py", line 395, in invalid_block_tag
    raise self.error(token, "Invalid block tag: '%s'" % command)
django.template.base.TemplateSyntaxError: Invalid block tag: 'SITE_NAME'
2016-12-01 15:44:39,141 [Thread-3:4124] [django.request:256] [base:handle_uncaught_exception] [ERROR]- Internal Server Error: /favicon.ico
Traceback (most recent call last):
  File "c:\python\python35\lib\site-packages\django\template\base.py", line 337, in parse
    compile_func = self.tags[command]
KeyError: 'SITE_NAME'

During handling of the above exception, another exception occurred:

Traceback (most recent call last):
  File "c:\python\python35\lib\site-packages\django\core\handlers\base.py", line 132, in get_response
    response = wrapped_callback(request, *callback_args, **callback_kwargs)
  File "C:\Users\array\PycharmProjects\www\blog\views.py", line 11, in index
    return render(request,'index.html',locals())
  File "c:\python\python35\lib\site-packages\django\shortcuts.py", line 67, in render
    template_name, context, request=request, using=using)
  File "c:\python\python35\lib\site-packages\django\template\loader.py", line 98, in render_to_string
    template = get_template(template_name, using=using)
  File "c:\python\python35\lib\site-packages\django\template\loader.py", line 35, in get_template
    return engine.get_template(template_name, dirs)
  File "c:\python\python35\lib\site-packages\django\template\backends\django.py", line 30, in get_template
    return Template(self.engine.get_template(template_name, dirs))
  File "c:\python\python35\lib\site-packages\django\template\engine.py", line 167, in get_template
    template, origin = self.find_template(template_name, dirs)
  File "c:\python\python35\lib\site-packages\django\template\engine.py", line 141, in find_template
    source, display_name = loader(name, dirs)
  File "c:\python\python35\lib\site-packages\django\template\loaders\base.py", line 13, in __call__
    return self.load_template(template_name, template_dirs)
  File "c:\python\python35\lib\site-packages\django\template\loaders\base.py", line 23, in load_template
    template = Template(source, origin, template_name, self.engine)
  File "c:\python\python35\lib\site-packages\django\template\base.py", line 190, in __init__
    self.nodelist = engine.compile_string(template_string, origin)
  File "c:\python\python35\lib\site-packages\django\template\engine.py", line 261, in compile_string
    return parser.parse()
  File "c:\python\python35\lib\site-packages\django\template\base.py", line 339, in parse
    self.invalid_block_tag(token, command, parse_until)
  File "c:\python\python35\lib\site-packages\django\template\base.py", line 395, in invalid_block_tag
    raise self.error(token, "Invalid block tag: '%s'" % command)
django.template.base.TemplateSyntaxError: Invalid block tag: 'SITE_NAME'
2016-12-01 15:52:19,064 [Thread-2:15660] [django.request:256] [base:handle_uncaught_exception] [ERROR]- Internal Server Error: /
Traceback (most recent call last):
  File "c:\python\python35\lib\site-packages\django\template\base.py", line 337, in parse
    compile_func = self.tags[command]
KeyError: 'SITE_NAME'

During handling of the above exception, another exception occurred:

Traceback (most recent call last):
  File "c:\python\python35\lib\site-packages\django\core\handlers\base.py", line 132, in get_response
    response = wrapped_callback(request, *callback_args, **callback_kwargs)
  File "C:\Users\array\PycharmProjects\www\blog\views.py", line 17, in index
    return render(request,'index.html',locals())
  File "c:\python\python35\lib\site-packages\django\shortcuts.py", line 67, in render
    template_name, context, request=request, using=using)
  File "c:\python\python35\lib\site-packages\django\template\loader.py", line 98, in render_to_string
    template = get_template(template_name, using=using)
  File "c:\python\python35\lib\site-packages\django\template\loader.py", line 35, in get_template
    return engine.get_template(template_name, dirs)
  File "c:\python\python35\lib\site-packages\django\template\backends\django.py", line 30, in get_template
    return Template(self.engine.get_template(template_name, dirs))
  File "c:\python\python35\lib\site-packages\django\template\engine.py", line 167, in get_template
    template, origin = self.find_template(template_name, dirs)
  File "c:\python\python35\lib\site-packages\django\template\engine.py", line 141, in find_template
    source, display_name = loader(name, dirs)
  File "c:\python\python35\lib\site-packages\django\template\loaders\base.py", line 13, in __call__
    return self.load_template(template_name, template_dirs)
  File "c:\python\python35\lib\site-packages\django\template\loaders\base.py", line 23, in load_template
    template = Template(source, origin, template_name, self.engine)
  File "c:\python\python35\lib\site-packages\django\template\base.py", line 190, in __init__
    self.nodelist = engine.compile_string(template_string, origin)
  File "c:\python\python35\lib\site-packages\django\template\engine.py", line 261, in compile_string
    return parser.parse()
  File "c:\python\python35\lib\site-packages\django\template\base.py", line 339, in parse
    self.invalid_block_tag(token, command, parse_until)
  File "c:\python\python35\lib\site-packages\django\template\base.py", line 395, in invalid_block_tag
    raise self.error(token, "Invalid block tag: '%s'" % command)
django.template.base.TemplateSyntaxError: Invalid block tag: 'SITE_NAME'
2016-12-01 15:52:19,420 [Thread-3:2888] [django.request:256] [base:handle_uncaught_exception] [ERROR]- Internal Server Error: /favicon.ico
Traceback (most recent call last):
  File "c:\python\python35\lib\site-packages\django\template\base.py", line 337, in parse
    compile_func = self.tags[command]
KeyError: 'SITE_NAME'

During handling of the above exception, another exception occurred:

Traceback (most recent call last):
  File "c:\python\python35\lib\site-packages\django\core\handlers\base.py", line 132, in get_response
    response = wrapped_callback(request, *callback_args, **callback_kwargs)
  File "C:\Users\array\PycharmProjects\www\blog\views.py", line 17, in index
    return render(request,'index.html',locals())
  File "c:\python\python35\lib\site-packages\django\shortcuts.py", line 67, in render
    template_name, context, request=request, using=using)
  File "c:\python\python35\lib\site-packages\django\template\loader.py", line 98, in render_to_string
    template = get_template(template_name, using=using)
  File "c:\python\python35\lib\site-packages\django\template\loader.py", line 35, in get_template
    return engine.get_template(template_name, dirs)
  File "c:\python\python35\lib\site-packages\django\template\backends\django.py", line 30, in get_template
    return Template(self.engine.get_template(template_name, dirs))
  File "c:\python\python35\lib\site-packages\django\template\engine.py", line 167, in get_template
    template, origin = self.find_template(template_name, dirs)
  File "c:\python\python35\lib\site-packages\django\template\engine.py", line 141, in find_template
    source, display_name = loader(name, dirs)
  File "c:\python\python35\lib\site-packages\django\template\loaders\base.py", line 13, in __call__
    return self.load_template(template_name, template_dirs)
  File "c:\python\python35\lib\site-packages\django\template\loaders\base.py", line 23, in load_template
    template = Template(source, origin, template_name, self.engine)
  File "c:\python\python35\lib\site-packages\django\template\base.py", line 190, in __init__
    self.nodelist = engine.compile_string(template_string, origin)
  File "c:\python\python35\lib\site-packages\django\template\engine.py", line 261, in compile_string
    return parser.parse()
  File "c:\python\python35\lib\site-packages\django\template\base.py", line 339, in parse
    self.invalid_block_tag(token, command, parse_until)
  File "c:\python\python35\lib\site-packages\django\template\base.py", line 395, in invalid_block_tag
    raise self.error(token, "Invalid block tag: '%s'" % command)
django.template.base.TemplateSyntaxError: Invalid block tag: 'SITE_NAME'
2016-12-01 15:54:03,584 [Thread-8:8820] [django.request:256] [base:handle_uncaught_exception] [ERROR]- Internal Server Error: /
Traceback (most recent call last):
  File "c:\python\python35\lib\site-packages\django\core\handlers\base.py", line 132, in get_response
    response = wrapped_callback(request, *callback_args, **callback_kwargs)
  File "C:\Users\array\PycharmProjects\www\blog\views.py", line 17, in index
    return render(request,'index.html',locals())
  File "c:\python\python35\lib\site-packages\django\shortcuts.py", line 67, in render
    template_name, context, request=request, using=using)
  File "c:\python\python35\lib\site-packages\django\template\loader.py", line 99, in render_to_string
    return template.render(context, request)
  File "c:\python\python35\lib\site-packages\django\template\backends\django.py", line 74, in render
    return self.template.render(context)
  File "c:\python\python35\lib\site-packages\django\template\base.py", line 208, in render
    with context.bind_template(self):
  File "c:\python\python35\Lib\contextlib.py", line 59, in __enter__
    return next(self.gen)
  File "c:\python\python35\lib\site-packages\django\template\context.py", line 235, in bind_template
    updates.update(processor(self.request))
TypeError: global_setting() takes 0 positional arguments but 1 was given
2016-12-01 15:54:04,011 [Thread-9:5824] [django.request:256] [base:handle_uncaught_exception] [ERROR]- Internal Server Error: /favicon.ico
Traceback (most recent call last):
  File "c:\python\python35\lib\site-packages\django\core\handlers\base.py", line 132, in get_response
    response = wrapped_callback(request, *callback_args, **callback_kwargs)
  File "C:\Users\array\PycharmProjects\www\blog\views.py", line 17, in index
    return render(request,'index.html',locals())
  File "c:\python\python35\lib\site-packages\django\shortcuts.py", line 67, in render
    template_name, context, request=request, using=using)
  File "c:\python\python35\lib\site-packages\django\template\loader.py", line 99, in render_to_string
    return template.render(context, request)
  File "c:\python\python35\lib\site-packages\django\template\backends\django.py", line 74, in render
    return self.template.render(context)
  File "c:\python\python35\lib\site-packages\django\template\base.py", line 208, in render
    with context.bind_template(self):
  File "c:\python\python35\Lib\contextlib.py", line 59, in __enter__
    return next(self.gen)
  File "c:\python\python35\lib\site-packages\django\template\context.py", line 235, in bind_template
    updates.update(processor(self.request))
TypeError: global_setting() takes 0 positional arguments but 1 was given
2016-12-01 15:54:50,524 [Thread-2:10444] [django.request:256] [base:handle_uncaught_exception] [ERROR]- Internal Server Error: /
Traceback (most recent call last):
  File "c:\python\python35\lib\site-packages\django\template\base.py", line 337, in parse
    compile_func = self.tags[command]
KeyError: 'static'

During handling of the above exception, another exception occurred:

Traceback (most recent call last):
  File "c:\python\python35\lib\site-packages\django\core\handlers\base.py", line 132, in get_response
    response = wrapped_callback(request, *callback_args, **callback_kwargs)
  File "C:\Users\array\PycharmProjects\www\blog\views.py", line 17, in index
    return render(request,'index.html',locals())
  File "c:\python\python35\lib\site-packages\django\shortcuts.py", line 67, in render
    template_name, context, request=request, using=using)
  File "c:\python\python35\lib\site-packages\django\template\loader.py", line 98, in render_to_string
    template = get_template(template_name, using=using)
  File "c:\python\python35\lib\site-packages\django\template\loader.py", line 35, in get_template
    return engine.get_template(template_name, dirs)
  File "c:\python\python35\lib\site-packages\django\template\backends\django.py", line 30, in get_template
    return Template(self.engine.get_template(template_name, dirs))
  File "c:\python\python35\lib\site-packages\django\template\engine.py", line 167, in get_template
    template, origin = self.find_template(template_name, dirs)
  File "c:\python\python35\lib\site-packages\django\template\engine.py", line 141, in find_template
    source, display_name = loader(name, dirs)
  File "c:\python\python35\lib\site-packages\django\template\loaders\base.py", line 13, in __call__
    return self.load_template(template_name, template_dirs)
  File "c:\python\python35\lib\site-packages\django\template\loaders\base.py", line 23, in load_template
    template = Template(source, origin, template_name, self.engine)
  File "c:\python\python35\lib\site-packages\django\template\base.py", line 190, in __init__
    self.nodelist = engine.compile_string(template_string, origin)
  File "c:\python\python35\lib\site-packages\django\template\engine.py", line 261, in compile_string
    return parser.parse()
  File "c:\python\python35\lib\site-packages\django\template\base.py", line 339, in parse
    self.invalid_block_tag(token, command, parse_until)
  File "c:\python\python35\lib\site-packages\django\template\base.py", line 395, in invalid_block_tag
    raise self.error(token, "Invalid block tag: '%s'" % command)
django.template.base.TemplateSyntaxError: Invalid block tag: 'static'
2016-12-01 15:54:50,865 [Thread-5:4224] [django.request:256] [base:handle_uncaught_exception] [ERROR]- Internal Server Error: /favicon.ico
Traceback (most recent call last):
  File "c:\python\python35\lib\site-packages\django\template\base.py", line 337, in parse
    compile_func = self.tags[command]
KeyError: 'static'

During handling of the above exception, another exception occurred:

Traceback (most recent call last):
  File "c:\python\python35\lib\site-packages\django\core\handlers\base.py", line 132, in get_response
    response = wrapped_callback(request, *callback_args, **callback_kwargs)
  File "C:\Users\array\PycharmProjects\www\blog\views.py", line 17, in index
    return render(request,'index.html',locals())
  File "c:\python\python35\lib\site-packages\django\shortcuts.py", line 67, in render
    template_name, context, request=request, using=using)
  File "c:\python\python35\lib\site-packages\django\template\loader.py", line 98, in render_to_string
    template = get_template(template_name, using=using)
  File "c:\python\python35\lib\site-packages\django\template\loader.py", line 35, in get_template
    return engine.get_template(template_name, dirs)
  File "c:\python\python35\lib\site-packages\django\template\backends\django.py", line 30, in get_template
    return Template(self.engine.get_template(template_name, dirs))
  File "c:\python\python35\lib\site-packages\django\template\engine.py", line 167, in get_template
    template, origin = self.find_template(template_name, dirs)
  File "c:\python\python35\lib\site-packages\django\template\engine.py", line 141, in find_template
    source, display_name = loader(name, dirs)
  File "c:\python\python35\lib\site-packages\django\template\loaders\base.py", line 13, in __call__
    return self.load_template(template_name, template_dirs)
  File "c:\python\python35\lib\site-packages\django\template\loaders\base.py", line 23, in load_template
    template = Template(source, origin, template_name, self.engine)
  File "c:\python\python35\lib\site-packages\django\template\base.py", line 190, in __init__
    self.nodelist = engine.compile_string(template_string, origin)
  File "c:\python\python35\lib\site-packages\django\template\engine.py", line 261, in compile_string
    return parser.parse()
  File "c:\python\python35\lib\site-packages\django\template\base.py", line 339, in parse
    self.invalid_block_tag(token, command, parse_until)
  File "c:\python\python35\lib\site-packages\django\template\base.py", line 395, in invalid_block_tag
    raise self.error(token, "Invalid block tag: '%s'" % command)
django.template.base.TemplateSyntaxError: Invalid block tag: 'static'
2016-12-01 15:55:29,000 [Thread-3:6392] [django.request:256] [base:handle_uncaught_exception] [ERROR]- Internal Server Error: /
Traceback (most recent call last):
  File "c:\python\python35\lib\site-packages\django\core\handlers\base.py", line 132, in get_response
    response = wrapped_callback(request, *callback_args, **callback_kwargs)
  File "C:\Users\array\PycharmProjects\www\blog\views.py", line 17, in index
    return render(request,'index.html',locals())
  File "c:\python\python35\lib\site-packages\django\shortcuts.py", line 67, in render
    template_name, context, request=request, using=using)
  File "c:\python\python35\lib\site-packages\django\template\loader.py", line 99, in render_to_string
    return template.render(context, request)
  File "c:\python\python35\lib\site-packages\django\template\backends\django.py", line 74, in render
    return self.template.render(context)
  File "c:\python\python35\lib\site-packages\django\template\base.py", line 208, in render
    with context.bind_template(self):
  File "c:\python\python35\Lib\contextlib.py", line 59, in __enter__
    return next(self.gen)
  File "c:\python\python35\lib\site-packages\django\template\context.py", line 235, in bind_template
    updates.update(processor(self.request))
TypeError: global_setting() takes 0 positional arguments but 1 was given
2016-12-01 15:55:29,250 [Thread-2:7972] [django.request:256] [base:handle_uncaught_exception] [ERROR]- Internal Server Error: /favicon.ico
Traceback (most recent call last):
  File "c:\python\python35\lib\site-packages\django\core\handlers\base.py", line 132, in get_response
    response = wrapped_callback(request, *callback_args, **callback_kwargs)
  File "C:\Users\array\PycharmProjects\www\blog\views.py", line 17, in index
    return render(request,'index.html',locals())
  File "c:\python\python35\lib\site-packages\django\shortcuts.py", line 67, in render
    template_name, context, request=request, using=using)
  File "c:\python\python35\lib\site-packages\django\template\loader.py", line 99, in render_to_string
    return template.render(context, request)
  File "c:\python\python35\lib\site-packages\django\template\backends\django.py", line 74, in render
    return self.template.render(context)
  File "c:\python\python35\lib\site-packages\django\template\base.py", line 208, in render
    with context.bind_template(self):
  File "c:\python\python35\Lib\contextlib.py", line 59, in __enter__
    return next(self.gen)
  File "c:\python\python35\lib\site-packages\django\template\context.py", line 235, in bind_template
    updates.update(processor(self.request))
TypeError: global_setting() takes 0 positional arguments but 1 was given
2016-12-01 15:58:13,328 [Thread-2:17896] [django.request:256] [base:handle_uncaught_exception] [ERROR]- Internal Server Error: /
Traceback (most recent call last):
  File "c:\python\python35\lib\site-packages\django\core\handlers\base.py", line 132, in get_response
    response = wrapped_callback(request, *callback_args, **callback_kwargs)
  File "C:\Users\array\PycharmProjects\www\blog\views.py", line 17, in index
    return render(request,'index.html',locals())
  File "c:\python\python35\lib\site-packages\django\shortcuts.py", line 67, in render
    template_name, context, request=request, using=using)
  File "c:\python\python35\lib\site-packages\django\template\loader.py", line 99, in render_to_string
    return template.render(context, request)
  File "c:\python\python35\lib\site-packages\django\template\backends\django.py", line 74, in render
    return self.template.render(context)
  File "c:\python\python35\lib\site-packages\django\template\base.py", line 208, in render
    with context.bind_template(self):
  File "c:\python\python35\Lib\contextlib.py", line 59, in __enter__
    return next(self.gen)
  File "c:\python\python35\lib\site-packages\django\template\context.py", line 235, in bind_template
    updates.update(processor(self.request))
TypeError: global_setting() takes 0 positional arguments but 1 was given
2016-12-01 15:58:13,572 [Thread-3:8464] [django.request:256] [base:handle_uncaught_exception] [ERROR]- Internal Server Error: /favicon.ico
Traceback (most recent call last):
  File "c:\python\python35\lib\site-packages\django\core\handlers\base.py", line 132, in get_response
    response = wrapped_callback(request, *callback_args, **callback_kwargs)
  File "C:\Users\array\PycharmProjects\www\blog\views.py", line 17, in index
    return render(request,'index.html',locals())
  File "c:\python\python35\lib\site-packages\django\shortcuts.py", line 67, in render
    template_name, context, request=request, using=using)
  File "c:\python\python35\lib\site-packages\django\template\loader.py", line 99, in render_to_string
    return template.render(context, request)
  File "c:\python\python35\lib\site-packages\django\template\backends\django.py", line 74, in render
    return self.template.render(context)
  File "c:\python\python35\lib\site-packages\django\template\base.py", line 208, in render
    with context.bind_template(self):
  File "c:\python\python35\Lib\contextlib.py", line 59, in __enter__
    return next(self.gen)
  File "c:\python\python35\lib\site-packages\django\template\context.py", line 235, in bind_template
    updates.update(processor(self.request))
TypeError: global_setting() takes 0 positional arguments but 1 was given
